Workbook

Sheet Distance (70 km)
B2: Valmo-SAVE · Resale radius: how far may a held RTO travel to its next buyer?
B3: Answer: a 70 km network cap. Three independent methods on Olist back-tests (Apr–Jul 2018, unseen) + the freight cliff + a Delhi NCR check. All derived numbers are live formulas.
B5: 0 · THE ANSWER (live)
B6: Each line is a formula pointing at the calculation further down this tab.
B8: Result | C8: Value | D8: How it is computed
B9: Method 1 · all products (26,767 RTOs) | C9: =$E$126 -> 65 | D9: Average of 4 lens elbows (one curve, region types, categories, category × region) · section 3 | AE9: Method | AF9: km
B10: Method 2 · top-20 SKUs (1,487 RTOs) | C10: =$J$173 -> 70 | D10: RTO-weighted mean of the per-SKU elbows · section 4 | AE10: All products | AF10: =$E$126 -> 65
B11: Method 3 · São Paulo metro (209 SKUs) | C11: =$G$216 -> 45 | D11: RTO-weighted mean of 209 SKU elbows · section 5 + appendix | AE11: Top-20 SKUs | AF11: =$J$173 -> 70
B12: Average of the three methods | C12: =ROUND(AVERAGE(C9:C11),0) -> 60 | D12: Simple average, for reference | AE12: São Paulo | AF12: =$G$216 -> 45
B13: NETWORK CAP (largest of the three methods) | C13: =MAX(C9:C11) -> 70 | D13: Covers the SKUs that earn the most (top-20) and stays inside the city network | AE13: Average | AF13: =C12 -> 60
B14: Metros: share of value already reached at the cap | C14: =$I$49 -> 0.88874189 | D14: Engine re-run at each radius · section 2 | AE14: Network cap | AF14: =C13 -> 70
B15: Freight just past 100 km (vs ≤ 25 km) | C15: =$G$248 -> 0.42744657 | D15: Olist delivery costs · section 6 — the cap stays below this cliff
B16: Top-20 SKUs that already pay inside the cap | C16: =$I$309 -> 17 of 20 | D16: Per-SKU break-even radius · section 7b
B17: Delhi NCR towns inside the cap | C17: =$F$367 -> 12 of 16 | D17: Haversine from Connaught Place · section 9
B18: ₹ saved per RTO at the cap: all Brazil / metros | C18: =TEXT($I$52,"₹0.00")&" / "&TEXT($I$53,"₹0.00") -> ₹3.54 / ₹9.81 | D18: Engine back-test on unseen months · section 2
B20: 1 · COST INPUTS (shared with the Time tab)
B21: Team workbook costs. Change a blue cell and every result on both tabs updates.
B23: Input | C23: Value | D23: Unit | E23: Source / meaning
B24: Forward delivery cost (already spent) | C24: 50 | D24: ₹ | E24: Meesho problem statement
B25: Reverse logistics cost (avoided when resold) | C25: 120 | D25: ₹ | E25: Meesho problem statement
B26: Status quo cost of an RTO | C26: =C24+C25 -> 170 | D26: ₹ | E26: Formula: forward + reverse
B27: Handling at the hub | C27: 15 | D27: ₹ | E27: Round-1 deck benchmark
B28: Relabel on resale | C28: 2 | D28: ₹ | E28: Round-1 deck benchmark
B29: Manpower | C29: 8 | D29: ₹ | E29: Round-1 deck benchmark
B30: One-time hold cost | C30: =C27+C28+C29 -> 25 | D30: ₹ | E30: Formula: handling + relabel + manpower
B31: Storage per 30 days | C31: 10 | D31: ₹ | E31: Round-1 deck benchmark
B32: Storage per day | C32: =C31/30 -> 0.33333333 | D32: ₹/day | E32: Formula
B33: Olist average freight per item | C33: 19.95 | D33: R$ | E33: Olist, 112k items; equals the ₹50 average journey
B34: ₹ per R$ of Olist freight (scale) | C34: =C24/C33 -> 2.5062657 | D34: ₹ per R$ | E34: Formula: puts Olist freight on Meesho's ₹50 scale
B35: Saving when a held RTO resells = ₹170 − (₹50 + ₹25 + storage × days) = ₹120 − ₹25 − storage × days.
B37: 2 · ENGINE RE-RUN AT EACH RADIUS (the slide curve)
B38: v2.2 engine back-test on 26,767 unseen RTOs (Apr–Jul 2018), re-run with only the resale radius changed. Metros = São Paulo + Rio "launch" areas (8,351 RTOs).
B40: Resale radius (km) | C40: All Brazil ₹ saved / RTO | D40: 95% low | E40: 95% high | F40: Held share | G40: Resold of held | H40: Metros ₹ / RTO | I40: Mid-size cities ₹ / RTO | J40: Small towns ₹ / RTO | K40: Metros: share of 200-km value | L40: Metros: extra ₹ per +10 km | M40: All Brazil: extra ₹ per +10 km
B41: 0 | C41: 0 | D41: 0 | E41: 0 | F41: 0 | H41: 0 | I41: 0 | J41: 0 | K41: =H41/INDEX($H$41:$H$48,MATCH(200,$B$41:$B$48,0)) -> 0
B42: 10 | C42: 0.3184 | D42: 0.0667 | E42: 0.6128 | F42: 0.0296 | G42: 0.3417 | H42: 1.0098 | I42: 0.0792 | J42: -0.0175 | K42: =H42/INDEX($H$41:$H$48,MATCH(200,$B$41:$B$48,0)) -> 0.09150386 | L42: =(H42-H41)/(B42-B41)*10 -> 1.0098 | M42: =(C42-C41)/(B42-B41)*10 -> 0.3184
B43: 25 | C43: 2.1386 | D43: 1.5404 | E43: 2.7289 | F43: 0.095 | G43: 0.4365 | H43: 6.6246 | I43: 0.5825 | J43: -0.0397 | K43: =H43/INDEX($H$41:$H$48,MATCH(200,$B$41:$B$48,0)) -> 0.6002936 | L43: =(H43-H42)/(B43-B42)*10 -> 3.7432 | M43: =(C43-C42)/(B43-B42)*10 -> 1.2134667
B44: 50 | C44: 3.1547 | D44: 2.3898 | E44: 3.9527 | F44: 0.1339 | G44: 0.4446 | H44: 9.3777 | I44: 0.8662 | J44: 0.1722 | K44: =H44/INDEX($H$41:$H$48,MATCH(200,$B$41:$B$48,0)) -> 0.84976802 | L44: =(H44-H43)/(B44-B43)*10 -> 1.10124 | M44: =(C44-C43)/(B44-B43)*10 -> 0.40644
B45: 70 | C45: 3.5355 | D45: 2.7158 | E45: 4.3672 | F45: 0.1604 | G45: 0.4322 | H45: 9.8078 | I45: 1.3873 | J45: 0.4817 | K45: =H45/INDEX($H$41:$H$48,MATCH(200,$B$41:$B$48,0)) -> 0.88874189 | L45: =(H45-H44)/(B45-B44)*10 -> 0.21505 | M45: =(C45-C44)/(B45-B44)*10 -> 0.1904
B46: 100 | C46: 4.1069 | D46: 3.1136 | E46: 5.0604 | F46: 0.1976 | G46: 0.4217 | H46: 10.267 | I46: 2.4986 | J46: 0.9567 | K46: =H46/INDEX($H$41:$H$48,MATCH(200,$B$41:$B$48,0)) -> 0.93035268 | L46: =(H46-H45)/(B46-B45)*10 -> 0.15306667 | M46: =(C46-C45)/(B46-B45)*10 -> 0.19046667
B47: 150 | C47: 4.953 | D47: 3.7734 | E47: 6.1186 | F47: 0.2388 | G47: 0.4212 | H47: 10.7743 | I47: 3.05 | J47: 2.0914 | K47: =H47/INDEX($H$41:$H$48,MATCH(200,$B$41:$B$48,0)) -> 0.97632208 | L47: =(H47-H46)/(B47-B46)*10 -> 0.10146 | M47: =(C47-C46)/(B47-B46)*10 -> 0.16922
...

Sheet Time (21 days)
B2: Valmo-SAVE · Holding time: how long may an RTO wait at the hub for a local buyer?
B3: Answer: a 21-day cap, inside Meesho's 45-day lost-shipment rule. Three methods on the same unseen back-test, the economics of one more day, and a per-SKU check at 70 km. All derived numbers are live formulas.
B5: 0 · THE ANSWER (live)
B6: Each line is a formula pointing at the calculation further down this tab.
B8: Result | C8: Value | D8: How it is computed
B9: Method 1 · all products (21,055 RTOs) | C9: =$E$160 -> 21 | D9: Average of 5 lens elbows · section 4 | AK9: days
B10: Method 2 · top-20 SKUs (1,303 RTOs) | C10: =$K$190 -> 15 | D10: Average of pooled elbow and RTO-weighted SKU elbows · section 5 | AJ10: All products | AK10: =$E$160 -> 21
B11: Method 3 · São Paulo metro (5,108 RTOs) | C11: =$E$210 -> 17 | D11: Average of pooled elbow and two SKU groups · section 6 | AJ11: Top-20 SKUs | AK11: =$K$190 -> 15
B12: Average of the three methods | C12: =ROUND(AVERAGE(C9:C11),0) -> 18 | D12: Simple average, for reference | AJ12: São Paulo | AK12: =$E$210 -> 17
B13: WHOLE-CATALOGUE HOLD CAP (largest of the three) | C13: =MAX(C9:C11) -> 21 | D13: One SOP number for every SKU; the per-day stop rule still releases weak SKUs earlier | AJ13: Average | AK13: =C12 -> 18
B14: Room under the 45-day rule (median lane) | C14: =$D$255 -> 25 | D14: Section 7: 45 − 3 NDR − 2 buffer − 2 × 7.1 lane days | AJ14: Hold cap | AK14: =C13 -> 21
B15: Effective cap per RTO | C15: ="min("&TEXT(C13,"0")&" d, own room)" -> min(21 d, own room) | D15: Section 7
B16: Share of 60-day saving captured at day 21 (all / top-20 / SP) | C16: =TEXT($G$98,"0%")&" / "&TEXT($H$98,"0%")&" / "&TEXT($I$98,"0%") -> 72% / 76% / 75% | D16: Section 2
B17: Extra ₹ per RTO per day: week 1 vs after day 21 (all products) | C17: =TEXT($E$107,"₹0.00")&" → "&TEXT($E$110,"₹0.00")&" ("&TEXT($E$113,"0.0")&"× less)" -> ₹0.26 → ₹0.06 (4.3× less) | D17: Section 3
B18: P required to hold 21 days vs held RTOs resold by day 21 | C18: =TEXT($C$100,"0.0%")&" vs "&TEXT($P$100,"0.0%") -> 26.7% vs 33.6% | D18: Section 2: the average held RTO clears the bar
B19: Top-20 SKUs that pay at 70 km and 21 days | C19: =$K$284 -> 20 of 20 | D19: Section 8
B21: 1 · THE ECONOMICS OF ONE MORE DAY
B22: Costs link to the Distance tab (green). A held RTO is worth holding only while its chance of resale beats P required = (hold cost + storage × days) ÷ reverse cost.
B24: Cost line | C24: Value | D24: Unit
B25: Forward cost (sunk) | C25: ='Distance (70 km)'!$C$24 -> 50 | D25: ₹
B26: Reverse cost (avoided if resold) | C26: ='Distance (70 km)'!$C$25 -> 120 | D26: ₹
B27: Status quo per RTO | C27: ='Distance (70 km)'!$C$26 -> 170 | D27: ₹
B28: One-time hold cost | C28: ='Distance (70 km)'!$C$30 -> 25 | D28: ₹
B29: Storage per day | C29: ='Distance (70 km)'!$C$32 -> 0.33333333 | D29: ₹/day
B31: E[cost](T) = 75 + storage × E[days] + 120 × (1 − P(T)) → HOLD if below ₹170, i.e. if P(T) ≥ (25 + storage × E[days]) ÷ 120
B33: 2 · THREE BACK-TESTED CURVES: ₹ saved per RTO for every hold cap from 1 to 60 days
B34: Method 1 = all products (21,055 RTOs) · Method 2 = top-20 SKUs (1,303) · Method 3 = São Paulo metro (5,108). Kneedle elbow on days 1–60.
B36: Hold cap (days) | C36: P required to hold (break-even) | D36: M1 ₹/RTO all products | E36: M2 ₹/RTO top-20 | F36: M3 ₹/RTO São Paulo | G36: M1 share of 60-day value | H36: M2 share | I36: M3 share | J36: M1 extra ₹ for this day | K36: M2 extra ₹ | L36: M3 extra ₹ | M36: M1 Kneedle score | N36: M2 Kneedle score | O36: M3 Kneedle score | P36: M1 held RTOs resold by now | Q36: M2 resold by now | R36: M3 resold by now
B37: 1 | C37: =($C$28+$C$29*B37)/$C$26 -> 0.21111111 | D37: -0.1097 | E37: 0.0829 | F37: -0.1804 | G37: =D37/D$96 -> -0.019934581 | H37: =E37/E$96 -> 0.0025462878 | I37: =F37/F$96 -> -0.010656459 | M37: =(D37-MIN(D$37:D$96))/(MAX(D$37:D$96)-MIN(D$37:D$96))-(B37-1)/59 -> 0 | N37: =(E37-MIN(E$37:E$96))/(MAX(E$37:E$96)-MIN(E$37:E$96))-(B37-1)/59 -> 0 | O37: =(F37-MIN(F$37:F$96))/(MAX(F$37:F$96)-MIN(F$37:F$96))-(B37-1)/59 -> 0 | P37: 0.048 | Q37: 0.1078 | R37: 0.0639
B38: 2 | C38: =($C$28+$C$29*B38)/$C$26 -> 0.21388889 | D38: 0.105 | E38: 3.1269 | F38: 0.83 | G38: =D38/D$96 -> 0.019080502 | H38: =E38/E$96 -> 0.096043272 | I38: =F38/F$96 -> 0.049029163 | J38: =D38-D37 -> 0.2147 | K38: =E38-E37 -> 3.044 | L38: =F38-F37 -> 1.0104 | M38: =(D38-MIN(D$37:D$96))/(MAX(D$37:D$96)-MIN(D$37:D$96))-(B38-1)/59 -> 0.021303382 | N38: =(E38-MIN(E$37:E$96))/(MAX(E$37:E$96)-MIN(E$37:E$96))-(B38-1)/59 -> 0.076786509 | O38: =(F38-MIN(F$37:F$96))/(MAX(F$37:F$96)-MIN(F$37:F$96))-(B38-1)/59 -> 0.042107139 | P38: 0.0798 | Q38: 0.1652 | R38: 0.1047
B39: 3 | C39: =($C$28+$C$29*B39)/$C$26 -> 0.21666667 | D39: 0.3447 | E39: 6.7644 | F39: 1.7037 | G39: =D39/D$96 -> 0.062638561 | H39: =E39/E$96 -> 0.20776971 | I39: =F39/F$96 -> 0.10063974 | J39: =D39-D38 -> 0.2397 | K39: =E39-E38 -> 3.6375 | L39: =F39-F38 -> 0.8737 | M39: =(D39-MIN(D$37:D$96))/(MAX(D$37:D$96)-MIN(D$37:D$96))-(B39-1)/59 -> 0.047060948 | N39: =(E39-MIN(E$37:E$96))/(MAX(E$37:E$96)-MIN(E$37:E$96))-(B39-1)/59 -> 0.17184901 | O39: =(F39-MIN(F$37:F$96))/(MAX(F$37:F$96)-MIN(F$37:F$96))-(B39-1)/59 -> 0.076224378 | P39: 0.1045 | Q39: 0.2125 | R39: 0.1382
B40: 4 | C40: =($C$28+$C$29*B40)/$C$26 -> 0.21944444 | D40: 0.5923 | E40: 9.1207 | F40: 2.8086 | G40: =D40/D$96 -> 0.1076322 | H40: =E40/E$96 -> 0.28014387 | I40: =F40/F$96 -> 0.1659076 | J40: =D40-D39 -> 0.2476 | K40: =E40-E39 -> 2.3563 | L40: =F40-F39 -> 1.1049 | M40: =(D40-MIN(D$37:D$96))/(MAX(D$37:D$96)-MIN(D$37:D$96))-(B40-1)/59 -> 0.074226036 | N40: =(E40-MIN(E$37:E$96))/(MAX(E$37:E$96)-MIN(E$37:E$96))-(B40-1)/59 -> 0.22745877 | O40: =(F40-MIN(F$37:F$96))/(MAX(F$37:F$96)-MIN(F$37:F$96))-(B40-1)/59 -> 0.12385489 | P40: 0.1312 | Q40: 0.2578 | R40: 0.1724
B41: 5 | C41: =($C$28+$C$29*B41)/$C$26 -> 0.22222222 | D41: 0.8296 | E41: 11.1144 | F41: 3.8181 | G41: =D41/D$96 -> 0.15075413 | H41: =E41/E$96 -> 0.34138071 | I41: =F41/F$96 -> 0.22554006 | J41: =D41-D40 -> 0.2373 | K41: =E41-E40 -> 1.9937 | L41: =F41-F40 -> 1.0095 | M41: =(D41-MIN(D$37:D$96))/(MAX(D$37:D$96)-MIN(D$37:D$96))-(B41-1)/59 -> 0.099556001 | N41: =(E41-MIN(E$37:E$96))/(MAX(E$37:E$96)-MIN(E$37:E$96))-(B41-1)/59 -> 0.27190278 | O41: =(F41-MIN(F$37:F$96))/(MAX(F$37:F$96)-MIN(F$37:F$96))-(B41-1)/59 -> 0.16590943 | P41: 0.1528 | Q41: 0.289 | R41: 0.1997
B42: 6 | C42: =($C$28+$C$29*B42)/$C$26 -> 0.225 | D42: 1.1087 | E42: 12.4224 | F42: 4.7863 | G42: =D42/D$96 -> 0.20147192 | H42: =E42/E$96 -> 0.38155615 | I42: =F42/F$96 -> 0.28273287 | J42: =D42-D41 -> 0.2791 | K42: =E42-E41 -> 1.308 | L42: =F42-F41 -> 0.9682 | M42: =(D42-MIN(D$37:D$96))/(MAX(D$37:D$96)-MIN(D$37:D$96))-(B42-1)/59 -> 0.13233336 | N42: =(E42-MIN(E$37:E$96))/(MAX(E$37:E$96)-MIN(E$37:E$96))-(B42-1)/59 -> 0.29523163 | O42: =(F42-MIN(F$37:F$96))/(MAX(F$37:F$96)-MIN(F$37:F$96))-(B42-1)/59 -> 0.20555004 | P42: 0.1721 | Q42: 0.3132 | R42: 0.2236
B43: 7 | C43: =($C$28+$C$29*B43)/$C$26 -> 0.22777778 | D43: 1.4445 | E43: 14.2591 | F43: 5.779 | G43: =D43/D$96 -> 0.26249319 | H43: =E43/E$96 -> 0.43797071 | I43: =F43/F$96 -> 0.34137293 | J43: =D43-D42 -> 0.3358 | K43: =E43-E42 -> 1.8367 | L43: =F43-F42 -> 0.9927 | M43: =(D43-MIN(D$37:D$96))/(MAX(D$37:D$96)-MIN(D$37:D$96))-(B43-1)/59 -> 0.17521281 | N43: =(E43-MIN(E$37:E$96))/(MAX(E$37:E$96)-MIN(E$37:E$96))-(B43-1)/59 -> 0.33484105 | O43: =(F43-MIN(F$37:F$96))/(MAX(F$37:F$96)-MIN(F$37:F$96))-(B43-1)/59 -> 0.24662265 | P43: 0.1906 | Q43: 0.3374 | R43: 0.246
B44: 8 | C44: =($C$28+$C$29*B44)/$C$26 -> 0.23055556 | D44: 1.7164 | E44: 15.3648 | F44: 6.6829 | G44: =D44/D$96 -> 0.3119026 | H44: =E44/E$96 -> 0.47193248 | I44: =F44/F$96 -> 0.39476747 | J44: =D44-D43 -> 0.2719 | K44: =E44-E43 -> 1.1057 | L44: =F44-F43 -> 0.9039 | M44: =(D44-MIN(D$37:D$96))/(MAX(D$37:D$96)-MIN(D$37:D$96))-(B44-1)/59 -> 0.20670737 | N44: =(E44-MIN(E$37:E$96))/(MAX(E$37:E$96)-MIN(E$37:E$96))-(B44-1)/59 -> 0.35194036 | O44: =(F44-MIN(F$37:F$96))/(MAX(F$37:F$96)-MIN(F$37:F$96))-(B44-1)/59 -> 0.28250503 | P44: 0.2067 | Q44: 0.3555 | R44: 0.2654
B45: 9 | C45: =($C$28+$C$29*B45)/$C$26 -> 0.23333333 | D45: 1.8699 | E45: 16.4392 | F45: 7.2177 | G45: =D45/D$96 -> 0.33979647 | H45: =E45/E$96 -> 0.50493286 | I45: =F45/F$96 -> 0.42635879 | J45: =D45-D44 -> 0.1535 | K45: =E45-E44 -> 1.0744 | L45: =F45-F44 -> 0.5348 | M45: =(D45-MIN(D$37:D$96))/(MAX(D$37:D$96)-MIN(D$37:D$96))-(B45-1)/59 -> 0.21710691 | N45: =(E45-MIN(E$37:E$96))/(MAX(E$37:E$96)-MIN(E$37:E$96))-(B45-1)/59 -> 0.36807583 | O45: =(F45-MIN(F$37:F$96))/(MAX(F$37:F$96)-MIN(F$37:F$96))-(B45-1)/59 -> 0.2968141 | P45: 0.2191 | Q45: 0.3716 | R45: 0.2802
B46: 10 | C46: =($C$28+$C$29*B46)/$C$26 -> 0.23611111 | D46: 2.194 | E46: 18.1074 | F46: 8.1077 | G46: =D46/D$96 -> 0.39869162 | H46: =E46/E$96 -> 0.55617191 | I46: =F46/F$96 -> 0.47893223 | J46: =D46-D45 -> 0.3241 | K46: =E46-E45 -> 1.6682 | L46: =F46-F45 -> 0.89 | M46: =(D46-MIN(D$37:D$96))/(MAX(D$37:D$96)-MIN(D$37:D$96))-(B46-1)/59 -> 0.2579018 | N46: =(E46-MIN(E$37:E$96))/(MAX(E$37:E$96)-MIN(E$37:E$96))-(B46-1)/59 -> 0.40249653 | O46: =(F46-MIN(F$37:F$96))/(MAX(F$37:F$96)-MIN(F$37:F$96))-(B46-1)/59 -> 0.33188404 | P46: 0.2335 | Q46: 0.3938 | R46: 0.2958
B47: 11 | C47: =($C$28+$C$29*B47)/$C$26 -> 0.23888889 | D47: 2.5282 | E47: 19.2458 | F47: 9.1935 | G47: =D47/D$96 -> 0.45942213 | H47: =E47/E$96 -> 0.59113806 | I47: =F47/F$96 -> 0.54307182 | J47: =D47-D46 -> 0.3342 | K47: =E47-E46 -> 1.1384 | L47: =F47-F46 -> 1.0858 | M47: =(D47-MIN(D$37:D$96))/(MAX(D$37:D$96)-MIN(D$37:D$96))-(B47-1)/59 -> 0.30049618 | N47: =(E47-MIN(E$37:E$96))/(MAX(E$37:E$96)-MIN(E$37:E$96))-(B47-1)/59 -> 0.4206028 | O47: =(F47-MIN(F$37:F$96))/(MAX(F$37:F$96)-MIN(F$37:F$96))-(B47-1)/59 -> 0.37839819 | P47: 0.2481 | Q47: 0.4099 | R47: 0.3141
B48: 12 | C48: =($C$28+$C$29*B48)/$C$26 -> 0.24166667 | D48: 2.7001 | E48: 19.9276 | F48: 9.6962 | G48: =D48/D$96 -> 0.49065964 | H48: =E48/E$96 -> 0.61207966 | I48: =F48/F$96 -> 0.57276696 | J48: =D48-D47 -> 0.1719 | K48: =E48-E47 -> 0.6818 | L48: =F48-F47 -> 0.5027 | M48: =(D48-MIN(D$37:D$96))/(MAX(D$37:D$96)-MIN(D$37:D$96))-(B48-1)/59 -> 0.314174 | N48: =(E48-MIN(E$37:E$96))/(MAX(E$37:E$96)-MIN(E$37:E$96))-(B48-1)/59 -> 0.42464871 | O48: =(F48-MIN(F$37:F$96))/(MAX(F$37:F$96)-MIN(F$37:F$96))-(B48-1)/59 -> 0.39083107 | P48: 0.2602 | Q48: 0.4199 | R48: 0.3286
...
