Workbook

Sheet Breakeven
A1: VALMO-SAVE · BREAKEVEN FOR A 21-DAY HOLD (per 100 held products)
A2: ="Answer: Out of every "&C5&" products held for up to "&C6&" days, at least "&C25&" (holding ₹"&TEXT(C10,"0")&") to "&D25&" (holding ₹"&TEXT(C11,"0")&") must be resold to break even." -> Answer: Out of every 100 products held for up to 21 days, at least 25 (holding ₹30) to 28 (holding ₹33) must be resold to break even.
A3: 1 · INPUTS
B4: Parameter | C4: Value | D4: Unit | E4: Note
B5: Products held at the LMDC | C5: 100 | D5: products | E5: Breakeven is shown per 100 held RTO products
B6: Maximum holding period | C6: 21 | D6: days | E6: Unsold products go back to the seller after 21 days
B7: Forward delivery cost | C7: 50 | D7: ₹/product | E7: Meesho case pack; already spent in every case
B8: Reverse logistics cost | C8: 120 | D8: ₹/product | E8: Meesho case pack; saved whenever a held product resells
B9: Status quo cost of one RTO | C9: =C7+C8 -> 170 | D9: ₹/product | E9: Forward + reverse (return at once)
B10: Holding cost per product · low case | C10: =Holding_Cost_21D!D14 -> 30 | D10: ₹/product | E10: From the Holding_Cost_21D tab
B11: Holding cost per product · high case | C11: =Holding_Cost_21D!E14 -> 33 | D11: ₹/product | E11: From the Holding_Cost_21D tab
B12: Previous model's holding cost (30-day hold) | C12: 35 | D12: ₹/product | E12: R1 model, for comparison only
A14: 2 · COST OF ONE PRODUCT UNDER EACH OUTCOME
B15: Outcome | C15: ="Holding ₹"&TEXT(C10,"0.00") -> Holding ₹30.00 | D15: ="Holding ₹"&TEXT(C11,"0.00") -> Holding ₹33.00 | E15: How it's calculated
B16: Return at once (status quo) | C16: =$C$9 -> 170 | D16: =$C$9 -> 170 | E16: Forward + reverse
B17: Held and resold within 21 days | C17: =$C$7+$C$10 -> 80 | D17: =$C$7+$C$11 -> 83 | E17: Forward + holding (no reverse trip)
B18: Held 21 days, not resold, then returned | C18: =$C$7+$C$10+$C$8 -> 200 | D18: =$C$7+$C$11+$C$8 -> 203 | E18: Forward + holding + reverse
B19: Saving on each product that resells | C19: =C16-C17 -> 90 | D19: =D16-D17 -> 87 | E19: Status quo − resold cost
B20: Extra cost on each product that does not | C20: =C18-C16 -> 30 | D20: =D18-D16 -> 33 | E20: Unsold cost − status quo (= the holding cost)
A22: 3 · BREAKEVEN: HOW MANY OF THE 100 MUST RESELL?
B23: Measure | C23: ="Holding ₹"&TEXT(C10,"0.00") -> Holding ₹30.00 | D23: ="Holding ₹"&TEXT(C11,"0.00") -> Holding ₹33.00 | E23: Formula
B24: Products to resell to break even (exact) | C24: =$C$5*C20/(C19+C20) -> 25 | D24: =$C$5*D20/(D19+D20) -> 27.5 | E24: products × extra cost ÷ (saving + extra cost)
B25: Products to resell (whole products) | C25: =ROUNDUP(C24,0) -> 25 | D25: =ROUNDUP(D24,0) -> 28 | E25: rounded up
B26: Breakeven resale rate | C26: =C24/$C$5 -> 0.25 | D26: =D24/$C$5 -> 0.275 | E26: share of held products that must resell
B27: Products that can stay unsold | C27: =$C$5-C25 -> 75 | D27: =$C$5-D25 -> 72 | E27: products − products to resell
B28: ="For comparison: previous 30-day model (₹"&TEXT(C12,"0")&" holding)" -> For comparison: previous 30-day model (₹35 holding) | C28: =$C$5*C12/$C$8 -> 29.166667 | D28: =ROUNDUP(C28,0) -> 30 | E28: ="21 days cuts the breakeven by "&(D28-D25)&"–"&(D28-C25)&" products per 100" -> 21 days cuts the breakeven by 2–5 products per 100
A30: 4 · BREAKEVEN TABLE (out of the held products above)
B31: Products resold | C31: Not resold | D31: Status quo cost (₹) | E31: ="Valmo-SAVE cost @ ₹"&TEXT(C10,"0") -> Valmo-SAVE cost @ ₹30 | F31: ="Saving @ ₹"&TEXT(C10,"0") -> Saving @ ₹30 | G31: ="Valmo-SAVE cost @ ₹"&TEXT(C11,"0") -> Valmo-SAVE cost @ ₹33 | H31: ="Saving @ ₹"&TEXT(C11,"0") -> Saving @ ₹33
B32: =0 -> 0 | C32: =$C$5-B32 -> 100 | D32: =$C$5*$C$9 -> 17000 | E32: =B32*$C$17+C32*$C$18 -> 20000 | F32: =D32-E32 -> -3000 | G32: =B32*$D$17+C32*$D$18 -> 20300 | H32: =D32-G32 -> -3300
B33: =B32+$C$5/20 -> 5 | C33: =$C$5-B33 -> 95 | D33: =$C$5*$C$9 -> 17000 | E33: =B33*$C$17+C33*$C$18 -> 19400 | F33: =D33-E33 -> -2400 | G33: =B33*$D$17+C33*$D$18 -> 19700 | H33: =D33-G33 -> -2700
B34: =B33+$C$5/20 -> 10 | C34: =$C$5-B34 -> 90 | D34: =$C$5*$C$9 -> 17000 | E34: =B34*$C$17+C34*$C$18 -> 18800 | F34: =D34-E34 -> -1800 | G34: =B34*$D$17+C34*$D$18 -> 19100 | H34: =D34-G34 -> -2100
B35: =B34+$C$5/20 -> 15 | C35: =$C$5-B35 -> 85 | D35: =$C$5*$C$9 -> 17000 | E35: =B35*$C$17+C35*$C$18 -> 18200 | F35: =D35-E35 -> -1200 | G35: =B35*$D$17+C35*$D$18 -> 18500 | H35: =D35-G35 -> -1500
B36: =B35+$C$5/20 -> 20 | C36: =$C$5-B36 -> 80 | D36: =$C$5*$C$9 -> 17000 | E36: =B36*$C$17+C36*$C$18 -> 17600 | F36: =D36-E36 -> -600 | G36: =B36*$D$17+C36*$D$18 -> 17900 | H36: =D36-G36 -> -900
B37: =B36+$C$5/20 -> 25 | C37: =$C$5-B37 -> 75 | D37: =$C$5*$C$9 -> 17000 | E37: =B37*$C$17+C37*$C$18 -> 17000 | F37: =D37-E37 -> 0 | G37: =B37*$D$17+C37*$D$18 -> 17300 | H37: =D37-G37 -> -300
B38: =B37+$C$5/20 -> 30 | C38: =$C$5-B38 -> 70 | D38: =$C$5*$C$9 -> 17000 | E38: =B38*$C$17+C38*$C$18 -> 16400 | F38: =D38-E38 -> 600 | G38: =B38*$D$17+C38*$D$18 -> 16700 | H38: =D38-G38 -> 300
B39: =B38+$C$5/20 -> 35 | C39: =$C$5-B39 -> 65 | D39: =$C$5*$C$9 -> 17000 | E39: =B39*$C$17+C39*$C$18 -> 15800 | F39: =D39-E39 -> 1200 | G39: =B39*$D$17+C39*$D$18 -> 16100 | H39: =D39-G39 -> 900
B40: =B39+$C$5/20 -> 40 | C40: =$C$5-B40 -> 60 | D40: =$C$5*$C$9 -> 17000 | E40: =B40*$C$17+C40*$C$18 -> 15200 | F40: =D40-E40 -> 1800 | G40: =B40*$D$17+C40*$D$18 -> 15500 | H40: =D40-G40 -> 1500
B41: =B40+$C$5/20 -> 45 | C41: =$C$5-B41 -> 55 | D41: =$C$5*$C$9 -> 17000 | E41: =B41*$C$17+C41*$C$18 -> 14600 | F41: =D41-E41 -> 2400 | G41: =B41*$D$17+C41*$D$18 -> 14900 | H41: =D41-G41 -> 2100
B42: =B41+$C$5/20 -> 50 | C42: =$C$5-B42 -> 50 | D42: =$C$5*$C$9 -> 17000 | E42: =B42*$C$17+C42*$C$18 -> 14000 | F42: =D42-E42 -> 3000 | G42: =B42*$D$17+C42*$D$18 -> 14300 | H42: =D42-G42 -> 2700
B43: =B42+$C$5/20 -> 55 | C43: =$C$5-B43 -> 45 | D43: =$C$5*$C$9 -> 17000 | E43: =B43*$C$17+C43*$C$18 -> 13400 | F43: =D43-E43 -> 3600 | G43: =B43*$D$17+C43*$D$18 -> 13700 | H43: =D43-G43 -> 3300
...

Sheet Holding_Cost_21D
A1: HOLDING COST · keeping one RTO product at the LMDC for up to 21 days
A3: # | B3: Cost line | C3: What it covers | D3: Low case (₹) | E3: High case (₹) | F3: Why this cost is taken · source
A4: 1 | B4: Storage (rack space) | C4: Shelf space in the LMDC RTO cage for up to 21 days | D4: =D17*Breakeven!$C$6/30 -> 6.3 | E4: =E17*Breakeven!$C$6/30 -> 7 | F4: Storage rate (row 18) × 21 ÷ 30 days. Benchmarks: Amazon India FBA storage ₹45–53 per cu ft per month × ~0.2 cu ft Meesho parcel ≈ ₹9–10.6 per 30 days; Delhi-NCR warehouse rent ₹21 per sq ft per month (Vestian, Aug 2025).
A5: 2 | B5: Inventory handling | C5: Inbound scan at the hold rack, put-away, pick-out | D5: 14 | E5: 15 | F5: Amazon India FBA pick & pack for a standard-size unit is about ₹14–17, so ₹14–15 is a fair LMDC handling cost.
A6: 3 | B6: Invoice & label regeneration | C6: New invoice and shipping label for the new buyer | D6: 1 | E6: 2 | F6: 4×6 direct-thermal label costs ₹0.60 (IndiaMART); the rest covers printing and invoice regeneration.
A7: 4 | B7: Additional manpower | C7: Daily count, seal/QC check, release to the shuttle | D7: 7 | E7: 7 | F7: About 3.7 minutes of a semi-skilled associate: Delhi minimum wage ₹20,371/month (from 1 Apr 2026) + 16.25% EPF/ESIC ≈ ₹1.90 per minute.
A8: 5 | B8: Packaging, damage & insurance allowance | C8: New outer bag when scuffed, small damage risk, stock cover | D8: 1.7 | E8: 2 | F8: Tamper-proof courier bag ₹3.63 (Flipkart, pack of 100) for about 1 in 4 units ≈ ₹0.90; SME stock insurance ≈ 0.07% a year (Policybazaar) ≈ ₹0.01; the rest is a damage allowance.
A9: ₹0 LINES · costs that do not add up for Valmo-SAVE, and why
A10: 6 | B10: LMDC → LMSC transfer | C10: Moving the product to the LMSC once a buyer is found | D10: 0 | E10: 0 | F10: ₹0. Valmo's vehicles already run to and fro between the LMDC and LMSC several times a day. The held product rides in spare space on a trip that runs anyway: no extra trip, fuel or driver hour. It fits the existing infrastructure.
A11: 7 | B11: Delivery to the new buyer | C11: LMSC → buyer's LMDC → last mile | D11: 0 | E11: 0 | F11: ₹0 extra. It is the new order's normal delivery, paid for like any order (it even skips first-mile pickup and line-haul).
A12: 8 | B12: Re-listing & marketing | C12: Finding a buyer for the product | D12: 0 | E12: 0 | F12: ₹0. The product is already listed on Meesho and is matched to an order a buyer has already placed. No ad spend, no discount: it is unopened and sells as new.
A13: 9 | B13: Racks, power & security | C13: Shelving, electricity, CCTV, guards | D13: 0 | E13: 0 | F13: ₹0 extra. Existing LMDC overheads; LMDCs already keep RTOs for a few days while they wait for reverse pickup.
B14: TOTAL HOLDING COST PER PRODUCT | C14: ="for a hold of up to "&Breakeven!$C$6&" days" -> for a hold of up to 21 days | D14: =SUM(D4:D8,D10:D13) -> 30 | E14: =SUM(E4:E8,E10:E13) -> 33 | F14: =IF(AND(D14>=D18,E14<=E18),"Within the ₹"&TEXT(D18,"0")&"–"&TEXT(E18,"0")&" target range","⚠ Outside the ₹"&TEXT(D18,"0")&"–"&TEXT(E18,"0")&" target range") -> Within the ₹30–33 target range
A16: INPUTS USED ABOVE
B17: Storage rate per product per 30 days | C17: Benchmark range (see row 5) | D17: 9 | E17: 10 | F17: ₹9–10 per 30 days ⇒ ₹0.30–0.33 per day.
B18: Target range for holding cost | C18: Per product, 21-day hold | D18: 30 | E18: 33 | F18: Used only for the ✓ check on the total.
A20: SOURCES
A21: 1 | B21: Meesho DICE Challenge 3.0 case pack | C21: Forward ₹50 and reverse ₹120 per RTO | F21: Case pack provided to participants
A22: 2 | B22: TheEcomWay · Amazon FBA fees in India (2025) | C22: Storage ₹45–53 per cu ft per month; pick & pack ≈ ₹14–17 per unit | F22: https://www.theecomway.com/blog/amazon-fba-fees-india-guide
A23: 3 | B23: Business Standard · Vestian report, 8 Aug 2025 | C23: Delhi-NCR warehouse rent ₹21 per sq ft per month | F23: https://www.business-standard.com/industry/news/delhi-ncr-sees-10-fall-in-rentals-of-warehousing-in-jan-jun-vestian-125080800989_1.html
A24: 4 | B24: ClearTax · Delhi minimum wages (from 1 Apr 2026) | C24: Semi-skilled worker ₹20,371 per month | F24: https://cleartax.in/s/minimum-wages-in-delhi
A25: 5 | B25: IndiaMART · 4×6 direct-thermal label | C25: ₹0.60 per label | F25: https://m.indiamart.com/proddetail/4-inch-x-6-inch-direct-thermal-shipping-label-22619895888.html
A26: 6 | B26: Flipkart · tamper-proof courier bags (pack of 100) | C26: ₹363 per pack ⇒ ₹3.63 per bag | F26: https://www.flipkart.com/piyush-courier-bags-poly-envlope-shipping-packing-mailing-microns-bag-10x12-tamper-proof-bags-pod-envelopes-pouches-cover-polybags-shipping-packing-mailing-10x12-courierbags10x12-white-black-pack-100/p/itmd849f7d3a2ea8
A27: 7 | B27: Policybazaar · Bharat Sookshma Udyam Suraksha | C27: ₹50 lakh stock cover from ₹283 per month ≈ 0.07% a year | F27: https://www.policybazaar.com/corporate-insurance/articles/bharat-sookshma-udyam-suraksha-insurance-policy/
